Workbook

Sheet INSTRUCCIONES
B2: GUÍA RÁPIDA: GENERACIÓN DE REPORTES
B5: PASO 1 | C5: Actualizar Movimientos
C6: Llene sus ingresos y gastos en la hoja 'Movimientos'. Use los desplegables.
B8: PASO 2 | C8: Guardar y Cerrar
C9: Guarde los cambios (Ctrl + G) y cierre el archivo Excel.
B11: PASO 3 | C11: Doble Clic
C12: Haga doble clic en el archivo 'GENERAR_REPORTES.bat' en su carpeta.
B14: PASO 4 | C14: ¡Listo!
C15: Sus reportes estarán en la carpeta 'reportes_generados' listos para enviar.

Sheet README
B2: ESTADO DE CUENTA DE FLOTA
B4: Sistema centralizado para administración de flota de terceros
B6: ESTRUCTURA DEL ARCHIVO
B7: Dueños | C7: Maestra de clientes. Cada dueño puede tener 1 o varios vehículos. Contiene nombre, documento, teléfono, WhatsApp y email (clave para envío automático).
B8: Vehículos | C8: Maestra de carros. Cada uno vinculado a su dueño vía dropdown. Placa, marca, modelo, año, fecha compra, costo y km inicial.
B9: Conductores | C9: Maestra de conductores. Nombre normalizado y tipo (fijo, ocasional, administrativo).
B10: Categorías | C10: Tipos de ingreso y gasto cerrados. Evita duplicados por errores de digitación.
B11: Movimientos | C11: TABLA PRINCIPAL. Todos los movimientos de todos los vehículos en una sola tabla. La columna "Placa" discrimina.
B12: KPIs | C12: Indicadores por vehículo. Selecciona placa arriba y todo se recalcula. Incluye descomposición de ingresos brutos, comisión admin y neto al dueño.
B13: Resumen Flota | C13: Vista consolidada para Juan Pablo: toda la flota listada con resultado por carro y totales generales.
B15: MODELO RELACIONAL
B16: 1 Dueño → puede tener varios Vehículos bajo administración
B17: 1 Vehículo → 1 Dueño a la vez, pero varios Conductores en el tiempo
B18: 1 Conductor → puede operar varios Vehículos
B19: Todo Movimiento queda vinculado a una Placa (→ Vehículo → Dueño) y a un Conductor
B21: FLUJO SEMANAL
B22: 1. Registrar movimientos (liquidaciones, gastos) en la hoja "Movimientos" usando dropdowns.
B23: 2. Si entra un dueño/vehículo/conductor nuevo → primero agregarlo en la hoja maestra correspondiente.
B24: 3. Al final de la semana, correr el generador de informes HTML (script externo).
B25: 4. Se genera 1 HTML por dueño + 1 HTML consolidado para Juan Pablo.
B26: 5. Enviar cada HTML al dueño correspondiente por WhatsApp. Cada uno ve SOLO su información.
B28: REGLAS DE ORO
... B34: ✓ SÍ describir el gasto con detalle.

Sheet Dueños
A1: Nombre completo | B1: Documento | C1: Teléfono | D1: WhatsApp | E1: Email | F1: Fecha inicio | G1: % Comisión | H1: Notas
A2: Joseph Restrepo | F2: 46006 | G2: 0.214 | H2: Dueño de UUO-808 — vehículo piloto del sistema
A3: Juan Pablo Bayona Areiza | G3: 0 | H3: Administrador de la flota
A4: (pendiente-1) | G4: 0.214 | H4: Completar cuando entre un nuevo dueño
A5: (pendiente-2) | G5: 0.214 | H5: Completar cuando entre un nuevo dueño
A6: (pendiente-3) | G6: 0.214 | H6: Completar cuando entre un nuevo dueño
A7: (pendiente-4) | G7: 0.214 | H7: Completar cuando entre un nuevo dueño
A8: (pendiente-5) | G8: 0.214 | H8: Completar cuando entre un nuevo dueño
A9: (pendiente-6) | G9: 0.214 | H9: Completar cuando entre un nuevo dueño
A10: (pendiente-7) | G10: 0.214 | H10: Completar cuando entre un nuevo dueño
A11: (pendiente-8) | G11: 0.214 | H11: Completar cuando entre un nuevo dueño
A12: (pendiente-9) | G12: 0.214 | H12: Completar cuando entre un nuevo dueño
A13: (pendiente-10) | G13: 0.214 | H13: Completar cuando entre un nuevo dueño
A14: (pendiente-11) | G14: 0.214 | H14: Completar cuando entre un nuevo dueño
... A21: (pendiente-18) | G21: 0.214 | H21: Completar cuando entre un nuevo dueño

Sheet Vehículos
A1: Placa | B1: Marca | C1: Modelo | D1: Año | E1: Dueño | F1: Fecha compra | G1: Costo adquisición | H1: Km al comprar | I1: Estado | J1: Notas
A2: UUO-808 | B2: Nissan | C2: March | D2: 2020 | E2: Joseph Restrepo | F2: 46006 | I2: Activo | J2: Vehículo piloto — data completa desde dic-2025
A3: ADMIN | B3: — | C3: — | E3: Juan Pablo Bayona Areiza | I3: Contable | J3: Entrada contable para movimientos administrativos
A4: (pendiente-1) | J4: Completar cuando entre un nuevo vehículo
A5: (pendiente-2) | J5: Completar cuando entre un nuevo vehículo
A6: (pendiente-3) | J6: Completar cuando entre un nuevo vehículo
A7: (pendiente-4) | J7: Completar cuando entre un nuevo vehículo
A8: (pendiente-5) | J8: Completar cuando entre un nuevo vehículo
A9: (pendiente-6) | J9: Completar cuando entre un nuevo vehículo
A10: (pendiente-7) | J10: Completar cuando entre un nuevo vehículo
A11: (pendiente-8) | J11: Completar cuando entre un nuevo vehículo
A12: (pendiente-9) | J12: Completar cuando entre un nuevo vehículo
A13: (pendiente-10) | J13: Completar cuando entre un nuevo vehículo
A14: (pendiente-11) | J14: Completar cuando entre un nuevo vehículo
A15: (pendiente-12) | J15: Completar cuando entre un nuevo vehículo
... A21: (pendiente-18) | J21: Completar cuando entre un nuevo vehículo

Sheet Conductores
A1: Nombre | B1: Tipo | C1: Documento | D1: Teléfono | E1: Notas
A2: Juan Pablo Bayona Areiza | B2: Administrativo | E2: Administra la flota
A3: José Daniel Otálvaro | B3: Fijo | E3: Conductor principal UUO-808
A4: Hernán Villada Villada | B4: Fijo
A5: Joseph Restrepo | B5: Propietario | E5: Dueño del vehículo UUO-808
A6: Otros conductores | B6: Ocasional | E6: Entrada genérica
A7: (pendiente-1)
A8: (pendiente-2)
A9: (pendiente-3)
A10: (pendiente-4)
A11: (pendiente-5)
A12: (pendiente-6)
A13: (pendiente-7)
A14: (pendiente-8)
A15: (pendiente-9)
A16: (pendiente-10)
A17: (pendiente-11)
A18: (pendiente-12)
... A21: (pendiente-15)

Sheet Categorías
A1: Categoría | B1: Tipo esperado | C1: Descripción | D1: Ejemplos
A2: Liquidación | B2: Ingreso | C2: Pago semanal del conductor por el alquiler del vehículo | D2: Liquidación semana del 01 al 07 de abril
A3: Ingreso administrativo | B3: Ingreso | C3: Ingresos no operativos (reembolsos, devoluciones) | D3: Reembolso del propietario
A4: Repuesto | B4: Gasto | C4: Piezas físicas compradas para el vehículo | D4: Retenedor, filtro, empaque, bujías
A5: Mantenimiento | B5: Gasto | C5: Servicios de mantenimiento rutinario o preventivo | D5: Cambio de aceite, lavado, alineación
A6: Mano de obra | B6: Gasto | C6: Pago por trabajo técnico realizado en el vehículo | D6: Cambio de aceite, rectificada, organización de llantas
A7: Accesorio | B7: Gasto | C7: Elementos adicionales instalados en el vehículo | D7: GPS, plumillas, polarizado, kit de carretera
A8: Gasto administrativo | B8: Gasto | C8: Comisión de Juan Pablo (21.4% de liquidaciones) y otros gastos admin | D8: Pago administración semanal, mototaxi
A9: Técnico mecánica | B9: Gasto | C9: Trámites obligatorios (revisión técnico-mecánica, SOAT) | D9: Revisión tecnomecánica anual

Sheet Movimientos
A1: Fecha | B1: Placa | C1: Conductor | D1: Tipo | E1: Categoría | F1: Descripción | G1: Km al momento | H1: Total | I1: Mes | J1: Validación
A2: 46006 | B2: UUO-808 | C2: Juan Pablo Bayona Areiza | D2: Gasto | E2: Mano de obra | F2: Se le hace organizar las llantas al vehículo; se le montan las que estan mas buenas | H2: -14000 | I2: =TEXT(A2,"yyyy-mm") | J2: =IF(D2="","",IF(AND(D2="Ingreso",H2>0),"OK",IF(AND(D2="Gasto",H2<0),"OK","⚠ Revisar signo")))
A3: 46006 | B3: ADMIN | C3: Joseph Restrepo | D3: Gasto | E3: Gasto administrativo | F3: Le pago a Joseph el moto taxi hasta la casa de el | H3: -14150 | I3: =TEXT(A3,"yyyy-mm") | J3: =IF(D3="","",IF(AND(D3="Ingreso",H3>0),"OK",IF(AND(D3="Gasto",H3<0),"OK","⚠ Revisar signo")))
A4: 46007 | B4: UUO-808 | C4: Juan Pablo Bayona Areiza | D4: Gasto | E4: Mantenimiento | F4: Se hace lavar el vehículo | H4: -23000 | I4: =TEXT(A4,"yyyy-mm") | J4: =IF(D4="","",IF(AND(D4="Ingreso",H4>0),"OK",IF(AND(D4="Gasto",H4<0),"OK","⚠ Revisar signo")))
A5: 46007 | B5: UUO-808 | C5: Juan Pablo Bayona Areiza | D5: Gasto | E5: Accesorio | F5: Se le compra la tapa del volante | H5: -300000 | I5: =TEXT(A5,"yyyy-mm") | J5: =IF(D5="","",IF(AND(D5="Ingreso",H5>0),"OK",IF(AND(D5="Gasto",H5<0),"OK","⚠ Revisar signo")))
A6: 46008 | B6: UUO-808 | C6: Juan Pablo Bayona Areiza | D6: Gasto | E6: Técnico mecánica | F6: Se realiza la revision tecnico mecanica | H6: -363600 | I6: =TEXT(A6,"yyyy-mm") | J6: =IF(D6="","",IF(AND(D6="Ingreso",H6>0),"OK",IF(AND(D6="Gasto",H6<0),"OK","⚠ Revisar signo")))
A7: 46009 | B7: UUO-808 | C7: Juan Pablo Bayona Areiza | D7: Gasto | E7: Accesorio | F7: GPS | H7: -340000 | I7: =TEXT(A7,"yyyy-mm") | J7: =IF(D7="","",IF(AND(D7="Ingreso",H7>0),"OK",IF(AND(D7="Gasto",H7<0),"OK","⚠ Revisar signo")))
A8: 46009 | B8: UUO-808 | C8: Juan Pablo Bayona Areiza | D8: Gasto | E8: Mantenimiento | F8: Se hace recargar el aire acondicionado | H8: -120000 | I8: =TEXT(A8,"yyyy-mm") | J8: =IF(D8="","",IF(AND(D8="Ingreso",H8>0),"OK",IF(AND(D8="Gasto",H8<0),"OK","⚠ Revisar signo")))
A9: 46009 | B9: UUO-808 | C9: Juan Pablo Bayona Areiza | D9: Gasto | E9: Accesorio | F9: Se hsce polarizar el vehículo | H9: -160000 | I9: =TEXT(A9,"yyyy-mm") | J9: =IF(D9="","",IF(AND(D9="Ingreso",H9>0),"OK",IF(AND(D9="Gasto",H9<0),"OK","⚠ Revisar signo")))
A10: 46010 | B10: UUO-808 | C10: Juan Pablo Bayona Areiza | D10: Gasto | E10: Accesorio | F10: Se compran las plumillas | H10: -20000 | I10: =TEXT(A10,"yyyy-mm") | J10: =IF(D10="","",IF(AND(D10="Ingreso",H10>0),"OK",IF(AND(D10="Gasto",H10<0),"OK","⚠ Revisar signo")))
A11: 46010 | B11: UUO-808 | C11: Juan Pablo Bayona Areiza | D11: Gasto | E11: Mano de obra | F11: Se le arregla el cilindro al vehiculo ya que se partio la llave de otro vehículo adentro | H11: -160000 | I11: =TEXT(A11,"yyyy-mm") | J11: =IF(D11="","",IF(AND(D11="Ingreso",H11>0),"OK",IF(AND(D11="Gasto",H11<0),"OK","⚠ Revisar signo")))
A12: 46010 | B12: UUO-808 | C12: Juan Pablo Bayona Areiza | D12: Gasto | E12: Mantenimiento | F12: Se hace alinear el vehículo | H12: -70000 | I12: =TEXT(A12,"yyyy-mm") | J12: =IF(D12="","",IF(AND(D12="Ingreso",H12>0),"OK",IF(AND(D12="Gasto",H12<0),"OK","⚠ Revisar signo")))
A13: 46010 | B13: UUO-808 | C13: Juan Pablo Bayona Areiza | D13: Gasto | E13: Gasto administrativo | F13: Se le echa gasolina al vehículo para poderlo entregar | H13: -20000 | I13: =TEXT(A13,"yyyy-mm") | J13: =IF(D13="","",IF(AND(D13="Ingreso",H13>0),"OK",IF(AND(D13="Gasto",H13<0),"OK","⚠ Revisar signo")))
... A35: 46043 | B35: UUO-808 | C35: Juan Pablo Bayona Areiza | D35: Gasto | E35: Gasto administrativo | F35: Se paga administrtación de la semana del 21 al 27 de enero | H35: -117700 | I35: =TEXT(A35,"yyyy-mm") | J35: =IF(D35="","",IF(AND(D35="Ingreso",H35>0),"OK",IF(AND(D35="Gasto",H35<0),"OK","⚠ Revisar signo")))
A36: 46050 | B36: UUO-808 | D36: Ingreso | E36: Liquidación | F36: Liquidación dias 31, 01, 02 y 03 de febrero | H36: 320000 | I36: =TEXT(A36,"yyyy-mm") | J36: =IF(D36="","",IF(AND(D36="Ingreso",H36>0),"OK",IF(AND(D36="Gasto",H36<0),"OK","⚠ Revisar signo")))
A37: 46050 | B37: UUO-808 | C37: Juan Pablo Bayona Areiza | D37: Gasto | E37: Gasto administrativo | F37: Se paga administrtación de los dias 31, 01, 02 y 03 de febrero | H37: -68480 | I37: =TEXT(A37,"yyyy-mm") | J37: =IF(D37="","",IF(AND(D37="Ingreso",H37>0),"OK",IF(AND(D37="Gasto",H37<0),"OK","⚠ Revisar signo")))
A38: 46050 | B38: UUO-808 | C38: Otros conductores | D38: Gasto | E38: Mano de obra | F38: Se paga el arreglo del aire acondicionado; se le organiza el sistema electrico porque estaba haciendo un corto y no enviaba corriente al compresor del aire | H38: -190000 | I38: =TEXT(A38,"yyyy-mm") | J38: =IF(D38="","",IF(AND(D38="Ingreso",H38>0),"OK",IF(AND(D38="Gasto",H38<0),"OK","⚠ Revisar signo")))
A39: 46051 | B39: UUO-808 | C39: Juan Pablo Bayona Areiza | D39: Gasto | E39: Repuesto | F39: Compro las tijeras del vehiculo porque una se doblo y la otra ya tenia el buje y la esfera mala | H39: -250000 | I39: =TEXT(A39,"yyyy-mm") | J39: =IF(D39="","",IF(AND(D39="Ingreso",H39>0),"OK",IF(AND(D39="Gasto",H39<0),"OK","⚠ Revisar signo")))
A40: 46060 | B40: UUO-808 | D40: Ingreso | E40: Liquidación | F40: Liquidación semana del 03 al 09 de febrero ( km) | H40: 480000 | I40: =TEXT(A40,"yyyy-mm") | J40: =IF(D40="","",IF(AND(D40="Ingreso",H40>0),"OK",IF(AND(D40="Gasto",H40<0),"OK","⚠ Revisar signo")))
A41: 46060 | B41: UUO-808 | C41: Juan Pablo Bayona Areiza | D41: Gasto | E41: Gasto administrativo | F41: Se paga administrtación de la semana del 03 al 09 de febrero | H41: -102720 | I41: =TEXT(A41,"yyyy-mm") | J41: =IF(D41="","",IF(AND(D41="Ingreso",H41>0),"OK",IF(AND(D41="Gasto",H41<0),"OK","⚠ Revisar signo")))
A42: 46064 | B42: UUO-808 | D42: Ingreso | E42: Liquidación | F42: Liquidación semana del 10 al 16 de febrero ( km) | H42: 480000 | I42: =TEXT(A42,"yyyy-mm") | J42: =IF(D42="","",IF(AND(D42="Ingreso",H42>0),"OK",IF(AND(D42="Gasto",H42<0),"OK","⚠ Revisar signo")))
A43: 46064 | B43: UUO-808 | C43: Juan Pablo Bayona Areiza | D43: Gasto | E43: Gasto administrativo | F43: Se paga administrtación de la semana del 03 al 09 de febrero | H43: -102720 | I43: =TEXT(A43,"yyyy-mm") | J43: =IF(D43="","",IF(AND(D43="Ingreso",H43>0),"OK",IF(AND(D43="Gasto",H43<0),"OK","⚠ Revisar signo")))
A44: 46070 | B44: UUO-808 | C44: Hernán Villada Villada | D44: Ingreso | E44: Liquidación | F44: Paga el dia martes 17 de febrero | H44: 80000 | I44: =TEXT(A44,"yyyy-mm") | J44: =IF(D44="","",IF(AND(D44="Ingreso",H44>0),"OK",IF(AND(D44="Gasto",H44<0),"OK","⚠ Revisar signo")))
A45: 46071 | B45: UUO-808 | C45: Hernán Villada Villada | D45: Ingreso | E45: Liquidación | F45: Liquidación semana del 18 al 24 de febrero (74232 km) | H45: 480000 | I45: =TEXT(A45,"yyyy-mm") | J45: =IF(D45="","",IF(AND(D45="Ingreso",H45>0),"OK",IF(AND(D45="Gasto",H45<0),"OK","⚠ Revisar signo")))
A46: 46071 | B46: UUO-808 | C46: Juan Pablo Bayona Areiza | D46: Gasto | E46: Gasto administrativo | F46: Se paga administrtación de los dias martes 17 de febrero y semana del 18 al 24 de febrero | H46: -119840 | I46: =TEXT(A46,"yyyy-mm") | J46: =IF(D46="","",IF(AND(D46="Ingreso",H46>0),"OK",IF(AND(D46="Gasto",H46<0),"OK","⚠ Revisar signo")))
A47: 46073 | B47: UUO-808 | C47: Hernán Villada Villada | D47: Gasto | E47: Mano de obra | F47: Se hace lavar el motor del vehiculo para identificar una posible fuga de aceitue de motor | H47: -30000 | I47: =TEXT(A47,"yyyy-mm") | J47: =IF(D47="","",IF(AND(D47="Ingreso",H47>0),"OK",IF(AND(D47="Gasto",H47<0),"OK","⚠ Revisar signo")))
A48: 46078 | B48: UUO-808 | C48: Hernán Villada Villada | D48: Ingreso | E48: Liquidación | F48: Liquidación semana del 25 de febrero al 03 de marzo ( km) | H48: 480000 | I48: =TEXT(A48,"yyyy-mm") | J48: =IF(D48="","",IF(AND(D48="Ingreso",H48>0),"OK",IF(AND(D48="Gasto",H48<0),"OK","⚠ Revisar signo")))
A49: 46078 | B49: UUO-808 | C49: Juan Pablo Bayona Areiza | D49: Gasto | E49: Gasto administrativo | F49: Se paga administrtación del 25 de febrero al 03 de marzo | H49: -102720 | I49: =TEXT(A49,"yyyy-mm") | J49: =IF(D49="","",IF(AND(D49="Ingreso",H49>0),"OK",IF(AND(D49="Gasto",H49<0),"OK","⚠ Revisar signo")))
A50: 46078 | B50: UUO-808 | C50: Hernán Villada Villada | D50: Gasto | E50: Repuesto | F50: Se le compran las pastas de freno delanteras | H50: -130000 | I50: =TEXT(A50,"yyyy-mm") | J50: =IF(D50="","",IF(AND(D50="Ingreso",H50>0),"OK",IF(AND(D50="Gasto",H50<0),"OK","⚠ Revisar signo")))
A51: 46078 | B51: UUO-808 | C51: Hernán Villada Villada | D51: Gasto | E51: Mano de obra | F51: Se le paga la mano obra del cambio de las pastas de freno delanteras | H51: -30000 | I51: =TEXT(A51,"yyyy-mm") | J51: =IF(D51="","",IF(AND(D51="Ingreso",H51>0),"OK",IF(AND(D51="Gasto",H51<0),"OK","⚠ Revisar signo")))
A52: 46085 | B52: UUO-808 | C52: Hernán Villada Villada | D52: Ingreso | E52: Liquidación | F52: Liquidación semana del 04 al 10 de marzo (77.076 Km) | H52: 480000 | I52: =TEXT(A52,"yyyy-mm") | J52: =IF(D52="","",IF(AND(D52="Ingreso",H52>0),"OK",IF(AND(D52="Gasto",H52<0),"OK","⚠ Revisar signo")))
A53: 46085 | B53: UUO-808 | C53: Hernán Villada Villada | D53: Gasto | E53: Gasto administrativo | F53: Se paga administrtación del 04 al 10 de febrero | H53: -102720 | I53: =TEXT(A53,"yyyy-mm") | J53: =IF(D53="","",IF(AND(D53="Ingreso",H53>0),"OK",IF(AND(D53="Gasto",H53<0),"OK","⚠ Revisar signo")))
A54: 46085 | B54: UUO-808 | C54: Hernán Villada Villada | D54: Gasto | E54: Accesorio | F54: Se compran dos bombillos para las fárolas y dos bombillos media | H54: -28000 | I54: =TEXT(A54,"yyyy-mm") | J54: =IF(D54="","",IF(AND(D54="Ingreso",H54>0),"OK",IF(AND(D54="Gasto",H54<0),"OK","⚠ Revisar signo")))
... A94: 46128 | B94: UUO-808 | C94: José Daniel Otálvaro | D94: Gasto | E94: Repuesto | F94: Retenedor del damper | H94: -30000 | I94: =TEXT(A94,"yyyy-mm") | J94: =IF(D94="","",IF(AND(D94="Ingreso",H94>0),"OK",IF(AND(D94="Gasto",H94<0),"OK","⚠ Revisar signo")))
I95: =IF(A95="","",TEXT(A95,"yyyy-mm")) | J95: =IF(D95="","",IF(AND(D95="Ingreso",H95>0),"OK",IF(AND(D95="Gasto",H95<0),"OK","⚠ Revisar signo")))
I96: =IF(A96="","",TEXT(A96,"yyyy-mm")) | J96: =IF(D96="","",IF(AND(D96="Ingreso",H96>0),"OK",IF(AND(D96="Gasto",H96<0),"OK","⚠ Revisar signo")))
I97: =IF(A97="","",TEXT(A97,"yyyy-mm")) | J97: =IF(D97="","",IF(AND(D97="Ingreso",H97>0),"OK",IF(AND(D97="Gasto",H97<0),"OK","⚠ Revisar signo")))
I98: =IF(A98="","",TEXT(A98,"yyyy-mm")) | J98: =IF(D98="","",IF(AND(D98="Ingreso",H98>0),"OK",IF(AND(D98="Gasto",H98<0),"OK","⚠ Revisar signo")))
I99: =IF(A99="","",TEXT(A99,"yyyy-mm")) | J99: =IF(D99="","",IF(AND(D99="Ingreso",H99>0),"OK",IF(AND(D99="Gasto",H99<0),"OK","⚠ Revisar signo")))
I100: =IF(A100="","",TEXT(A100,"yyyy-mm")) | J100: =IF(D100="","",IF(AND(D100="Ingreso",H100>0),"OK",IF(AND(D100="Gasto",H100<0),"OK","⚠ Revisar signo")))
...

Sheet KPIs
B2: INDICADORES POR VEHÍCULO | Z2: =IF(Movimientos!B2=$G$4,Movimientos!A2,"")
Z3: =IF(Movimientos!B3=$G$4,Movimientos!A3,"")
B4: Cambia la placa para ver los indicadores de otro vehículo → | G4: UUO-808 | Z4: =IF(Movimientos!B4=$G$4,Movimientos!A4,"")
B5: Dueño: | C5: =IFERROR(VLOOKUP(G4,Vehículos!A:E,5,FALSE()),"-") | Z5: =IF(Movimientos!B5=$G$4,Movimientos!A5,"")
Z6: =IF(Movimientos!B6=$G$4,Movimientos!A6,"")
B7: RESULTADO FINANCIERO | Z7: =IF(Movimientos!B7=$G$4,Movimientos!A7,"")
B8: INGRESOS BRUTOS | F8: =SUMIFS(Movimientos!H2:H594,Movimientos!B2:B594,G4,Movimientos!D2:D594,"Ingreso") | Z8: =IF(Movimientos!B8=$G$4,Movimientos!A8,"")
B9: COMISIÓN ADMINISTRACIÓN | F9: =SUMIFS(Movimientos!H2:H594,Movimientos!B2:B594,G4,Movimientos!E2:E594,"Gasto administrativo") | Z9: =IF(Movimientos!B9=$G$4,Movimientos!A9,"")
B10: GASTOS OPERATIVOS (repuestos, mano de obra, etc.) | F10: =SUMIFS(Movimientos!H2:H594,Movimientos!B2:B594,G4,Movimientos!D2:D594,"Gasto")-SUMIFS(Movimientos!H2:H594,Movimientos!B2:B594,G4,Movimientos!E2:E594,"Gasto administrativo") | Z10: =IF(Movimientos!B10=$G$4,Movimientos!A10,"")
B11: NETO AL DUEÑO | F11: =SUMIFS(Movimientos!H2:H594,Movimientos!B2:B594,G4) | Z11: =IF(Movimientos!B11=$G$4,Movimientos!A11,"")
B12: MARGEN % | F12: =IFERROR(SUMIFS(Movimientos!H2:H594,Movimientos!B2:B594,G4)/SUMIFS(Movimientos!H2:H594,Movimientos!B2:B594,G4,Movimientos!D2:D594,"Ingreso"),"-") | Z12: =IF(Movimientos!B12=$G$4,Movimientos!A12,"")
Z13: =IF(Movimientos!B13=$G$4,Movimientos!A13,"")
B14: OPERACIÓN | Z14: =IF(Movimientos!B14=$G$4,Movimientos!A14,"")
B15: # MOVIMIENTOS TOTALES | F15: =COUNTIF(Movimientos!B2:B594,G4) | Z15: =IF(Movimientos!B15=$G$4,Movimientos!A15,"")
B16: # LIQUIDACIONES | F16: =COUNTIFS(Movimientos!B2:B594,G4,Movimientos!E2:E594,"Liquidación") | Z16: =IF(Movimientos!B16=$G$4,Movimientos!A16,"")
B17: PRIMER MOVIMIENTO | F17: =IFERROR(MIN(Z:Z),"-") | Z17: =IF(Movimientos!B17=$G$4,Movimientos!A17,"")
B18: ÚLTIMO MOVIMIENTO | F18: =IFERROR(MAX(Z:Z),"-") | Z18: =IF(Movimientos!B18=$G$4,Movimientos!A18,"")
B19: DÍAS DE OPERACIÓN | F19: =IFERROR(MAX(Z:Z)-MIN(Z:Z)+1,"-") | Z19: =IF(Movimientos!B19=$G$4,Movimientos!A19,"")
B20: UTILIDAD POR DÍA | F20: =IFERROR(SUMIFS(Movimientos!H2:H594,Movimientos!B2:B594,G4)/(MAX(Z:Z)-MIN(Z:Z)+1),"-") | Z20: =IF(Movimientos!B20=$G$4,Movimientos!A20,"")
Z21: =IF(Movimientos!B21=$G$4,Movimientos!A21,"")
B22: GASTOS POR CATEGORÍA | Z22: =IF(Movimientos!B22=$G$4,Movimientos!A22,"")
B23: Categoría | F23: Total | G23: % del gasto | Z23: =IF(Movimientos!B23=$G$4,Movimientos!A23,"")
B24: Repuesto | F24: =SUMIFS(Movimientos!H2:H594,Movimientos!B2:B594,$G$4,Movimientos!E2:E594,B24) | G24: =IFERROR(F24/SUMIFS(Movimientos!H2:H594,Movimientos!B2:B594,$G$4,Movimientos!D2:D594,"Gasto"),"-") | Z24: =IF(Movimientos!B24=$G$4,Movimientos!A24,"")
B25: Mantenimiento | F25: =SUMIFS(Movimientos!H2:H594,Movimientos!B2:B594,$G$4,Movimientos!E2:E594,B25) | G25: =IFERROR(F25/SUMIFS(Movimientos!H2:H594,Movimientos!B2:B594,$G$4,Movimientos!D2:D594,"Gasto"),"-") | Z25: =IF(Movimientos!B25=$G$4,Movimientos!A25,"")
B26: Mano de obra | F26: =SUMIFS(Movimientos!H2:H594,Movimientos!B2:B594,$G$4,Movimientos!E2:E594,B26) | G26: =IFERROR(F26/SUMIFS(Movimientos!H2:H594,Movimientos!B2:B594,$G$4,Movimientos!D2:D594,"Gasto"),"-") | Z26: =IF(Movimientos!B26=$G$4,Movimientos!A26,"")
B27: Accesorio | F27: =SUMIFS(Movimientos!H2:H594,Movimientos!B2:B594,$G$4,Movimientos!E2:E594,B27) | G27: =IFERROR(F27/SUMIFS(Movimientos!H2:H594,Movimientos!B2:B594,$G$4,Movimientos!D2:D594,"Gasto"),"-") | Z27: =IF(Movimientos!B27=$G$4,Movimientos!A27,"")
B28: Gasto administrativo | F28: =SUMIFS(Movimientos!H2:H594,Movimientos!B2:B594,$G$4,Movimientos!E2:E594,B28) | G28: =IFERROR(F28/SUMIFS(Movimientos!H2:H594,Movimientos!B2:B594,$G$4,Movimientos!D2:D594,"Gasto"),"-") | Z28: =IF(Movimientos!B28=$G$4,Movimientos!A28,"")
B29: Técnico mecánica | F29: =SUMIFS(Movimientos!H2:H594,Movimientos!B2:B594,$G$4,Movimientos!E2:E594,B29) | G29: =IFERROR(F29/SUMIFS(Movimientos!H2:H594,Movimientos!B2:B594,$G$4,Movimientos!D2:D594,"Gasto"),"-") | Z29: =IF(Movimientos!B29=$G$4,Movimientos!A29,"")
B30: TOTAL | F30: =SUM(F24:F29) | G30: =SUM(G24:G29) | Z30: =IF(Movimientos!B30=$G$4,Movimientos!A30,"")
Z31: =IF(Movimientos!B31=$G$4,Movimientos!A31,"")
Z32: =IF(Movimientos!B32=$G$4,Movimientos!A32,"")
Z33: =IF(Movimientos!B33=$G$4,Movimientos!A33,"")
Z34: =IF(Movimientos!B34=$G$4,Movimientos!A34,"")
Z35: =IF(Movimientos!B35=$G$4,Movimientos!A35,"")
Z36: =IF(Movimientos!B36=$G$4,Movimientos!A36,"")
Z37: =IF(Movimientos!B37=$G$4,Movimientos!A37,"")
Z38: =IF(Movimientos!B38=$G$4,Movimientos!A38,"")
Z39: =IF(Movimientos!B39=$G$4,Movimientos!A39,"")
Z40: =IF(Movimientos!B40=$G$4,Movimientos!A40,"")
Z41: =IF(Movimientos!B41=$G$4,Movimientos!A41,"")
...

Sheet Resumen Flota
B2: RESUMEN CONSOLIDADO — VISTA JUAN PABLO
B3: Toda la flota listada con resultado por carro y totales generales de negocio
B5: Placa | C5: Dueño | D5: Estado | E5: Ingresos brutos | F5: Comisión admin | G5: Gastos operativos | H5: Neto dueño | I5: Margen % | J5: # Movs | K5: Semáforo
B6: =Vehículos!A2 | C6: =IFERROR(VLOOKUP(Vehículos!A2,Vehículos!A:E,5,FALSE()),"") | D6: =IFERROR(VLOOKUP(Vehículos!A2,Vehículos!A:I,9,FALSE()),"") | E6: =IFERROR(SUMIFS(Movimientos!H2:H594,Movimientos!B2:B594,Vehículos!A2,Movimientos!D2:D594,"Ingreso"),0) | F6: =IFERROR(SUMIFS(Movimientos!H2:H594,Movimientos!B2:B594,Vehículos!A2,Movimientos!E2:E594,"Gasto administrativo"),0) | G6: =IFERROR(SUMIFS(Movimientos!H2:H594,Movimientos!B2:B594,Vehículos!A2,Movimientos!D2:D594,"Gasto")-SUMIFS(Movimientos!H2:H594,Movimientos!B2:B594,Vehículos!A2,Movimientos!E2:E594,"Gasto administrativo"),0) | H6: =E6+F6+G6 | I6: =IFERROR(H6/E6,"-") | J6: =COUNTIF(Movimientos!B2:B594,Vehículos!A2) | K6: =IF(COUNTIF(Movimientos!B2:B594,Vehículos!A2)=0,"—",IF(H6>0,"🟢 Rentable",IF(H6>-500000,"🟡 Atención","🔴 Pérdida alta")))
B7: =Vehículos!A3 | C7: =IFERROR(VLOOKUP(Vehículos!A3,Vehículos!A:E,5,FALSE()),"") | D7: =IFERROR(VLOOKUP(Vehículos!A3,Vehículos!A:I,9,FALSE()),"") | E7: =IFERROR(SUMIFS(Movimientos!H2:H594,Movimientos!B2:B594,Vehículos!A3,Movimientos!D2:D594,"Ingreso"),0) | F7: =IFERROR(SUMIFS(Movimientos!H2:H594,Movimientos!B2:B594,Vehículos!A3,Movimientos!E2:E594,"Gasto administrativo"),0) | G7: =IFERROR(SUMIFS(Movimientos!H2:H594,Movimientos!B2:B594,Vehículos!A3,Movimientos!D2:D594,"Gasto")-SUMIFS(Movimientos!H2:H594,Movimientos!B2:B594,Vehículos!A3,Movimientos!E2:E594,"Gasto administrativo"),0) | H7: =E7+F7+G7 | I7: =IFERROR(H7/E7,"-") | J7: =COUNTIF(Movimientos!B2:B594,Vehículos!A3) | K7: =IF(COUNTIF(Movimientos!B2:B594,Vehículos!A3)=0,"—",IF(H7>0,"🟢 Rentable",IF(H7>-500000,"🟡 Atención","🔴 Pérdida alta")))
B8: =Vehículos!A4 | C8: =IFERROR(VLOOKUP(Vehículos!A4,Vehículos!A:E,5,FALSE()),"") | D8: =IFERROR(VLOOKUP(Vehículos!A4,Vehículos!A:I,9,FALSE()),"") | E8: =IFERROR(SUMIFS(Movimientos!H2:H594,Movimientos!B2:B594,Vehículos!A4,Movimientos!D2:D594,"Ingreso"),0) | F8: =IFERROR(SUMIFS(Movimientos!H2:H594,Movimientos!B2:B594,Vehículos!A4,Movimientos!E2:E594,"Gasto administrativo"),0) | G8: =IFERROR(SUMIFS(Movimientos!H2:H594,Movimientos!B2:B594,Vehículos!A4,Movimientos!D2:D594,"Gasto")-SUMIFS(Movimientos!H2:H594,Movimientos!B2:B594,Vehículos!A4,Movimientos!E2:E594,"Gasto administrativo"),0) | H8: =E8+F8+G8 | I8: =IFERROR(H8/E8,"-") | J8: =COUNTIF(Movimientos!B2:B594,Vehículos!A4) | K8: =IF(COUNTIF(Movimientos!B2:B594,Vehículos!A4)=0,"—",IF(H8>0,"🟢 Rentable",IF(H8>-500000,"🟡 Atención","🔴 Pérdida alta")))
B9: =Vehículos!A5 | C9: =IFERROR(VLOOKUP(Vehículos!A5,Vehículos!A:E,5,FALSE()),"") | D9: =IFERROR(VLOOKUP(Vehículos!A5,Vehículos!A:I,9,FALSE()),"") | E9: =IFERROR(SUMIFS(Movimientos!H2:H594,Movimientos!B2:B594,Vehículos!A5,Movimientos!D2:D594,"Ingreso"),0) | F9: =IFERROR(SUMIFS(Movimientos!H2:H594,Movimientos!B2:B594,Vehículos!A5,Movimientos!E2:E594,"Gasto administrativo"),0) | G9: =IFERROR(SUMIFS(Movimientos!H2:H594,Movimientos!B2:B594,Vehículos!A5,Movimientos!D2:D594,"Gasto")-SUMIFS(Movimientos!H2:H594,Movimientos!B2:B594,Vehículos!A5,Movimientos!E2:E594,"Gasto administrativo"),0) | H9: =E9+F9+G9 | I9: =IFERROR(H9/E9,"-") | J9: =COUNTIF(Movimientos!B2:B594,Vehículos!A5) | K9: =IF(COUNTIF(Movimientos!B2:B594,Vehículos!A5)=0,"—",IF(H9>0,"🟢 Rentable",IF(H9>-500000,"🟡 Atención","🔴 Pérdida alta")))
B10: =Vehículos!A6 | C10: =IFERROR(VLOOKUP(Vehículos!A6,Vehículos!A:E,5,FALSE()),"") | D10: =IFERROR(VLOOKUP(Vehículos!A6,Vehículos!A:I,9,FALSE()),"") | E10: =IFERROR(SUMIFS(Movimientos!H2:H594,Movimientos!B2:B594,Vehículos!A6,Movimientos!D2:D594,"Ingreso"),0) | F10: =IFERROR(SUMIFS(Movimientos!H2:H594,Movimientos!B2:B594,Vehículos!A6,Movimientos!E2:E594,"Gasto administrativo"),0) | G10: =IFERROR(SUMIFS(Movimientos!H2:H594,Movimientos!B2:B594,Vehículos!A6,Movimientos!D2:D594,"Gasto")-SUMIFS(Movimientos!H2:H594,Movimientos!B2:B594,Vehículos!A6,Movimientos!E2:E594,"Gasto administrativo"),0) | H10: =E10+F10+G10 | I10: =IFERROR(H10/E10,"-") | J10: =COUNTIF(Movimientos!B2:B594,Vehículos!A6) | K10: =IF(COUNTIF(Movimientos!B2:B594,Vehículos!A6)=0,"—",IF(H10>0,"🟢 Rentable",IF(H10>-500000,"🟡 Atención","🔴 Pérdida alta")))
B11: =Vehículos!A7 | C11: =IFERROR(VLOOKUP(Vehículos!A7,Vehículos!A:E,5,FALSE()),"") | D11: =IFERROR(VLOOKUP(Vehículos!A7,Vehículos!A:I,9,FALSE()),"") | E11: =IFERROR(SUMIFS(Movimientos!H2:H594,Movimientos!B2:B594,Vehículos!A7,Movimientos!D2:D594,"Ingreso"),0) | F11: =IFERROR(SUMIFS(Movimientos!H2:H594,Movimientos!B2:B594,Vehículos!A7,Movimientos!E2:E594,"Gasto administrativo"),0) | G11: =IFERROR(SUMIFS(Movimientos!H2:H594,Movimientos!B2:B594,Vehículos!A7,Movimientos!D2:D594,"Gasto")-SUMIFS(Movimientos!H2:H594,Movimientos!B2:B594,Vehículos!A7,Movimientos!E2:E594,"Gasto administrativo"),0) | H11: =E11+F11+G11 | I11: =IFERROR(H11/E11,"-") | J11: =COUNTIF(Movimientos!B2:B594,Vehículos!A7) | K11: =IF(COUNTIF(Movimientos!B2:B594,Vehículos!A7)=0,"—",IF(H11>0,"🟢 Rentable",IF(H11>-500000,"🟡 Atención","🔴 Pérdida alta")))
B12: =Vehículos!A8 | C12: =IFERROR(VLOOKUP(Vehículos!A8,Vehículos!A:E,5,FALSE()),"") | D12: =IFERROR(VLOOKUP(Vehículos!A8,Vehículos!A:I,9,FALSE()),"") | E12: =IFERROR(SUMIFS(Movimientos!H2:H594,Movimientos!B2:B594,Vehículos!A8,Movimientos!D2:D594,"Ingreso"),0) | F12: =IFERROR(SUMIFS(Movimientos!H2:H594,Movimientos!B2:B594,Vehículos!A8,Movimientos!E2:E594,"Gasto administrativo"),0) | G12: =IFERROR(SUMIFS(Movimientos!H2:H594,Movimientos!B2:B594,Vehículos!A8,Movimientos!D2:D594,"Gasto")-SUMIFS(Movimientos!H2:H594,Movimientos!B2:B594,Vehículos!A8,Movimientos!E2:E594,"Gasto administrativo"),0) | H12: =E12+F12+G12 | I12: =IFERROR(H12/E12,"-") | J12: =COUNTIF(Movimientos!B2:B594,Vehículos!A8) | K12: =IF(COUNTIF(Movimientos!B2:B594,Vehículos!A8)=0,"—",IF(H12>0,"🟢 Rentable",IF(H12>-500000,"🟡 Atención","🔴 Pérdida alta")))
B13: =Vehículos!A9 | C13: =IFERROR(VLOOKUP(Vehículos!A9,Vehículos!A:E,5,FALSE()),"") | D13: =IFERROR(VLOOKUP(Vehículos!A9,Vehículos!A:I,9,FALSE()),"") | E13: =IFERROR(SUMIFS(Movimientos!H2:H594,Movimientos!B2:B594,Vehículos!A9,Movimientos!D2:D594,"Ingreso"),0) | F13: =IFERROR(SUMIFS(Movimientos!H2:H594,Movimientos!B2:B594,Vehículos!A9,Movimientos!E2:E594,"Gasto administrativo"),0) | G13: =IFERROR(SUMIFS(Movimientos!H2:H594,Movimientos!B2:B594,Vehículos!A9,Movimientos!D2:D594,"Gasto")-SUMIFS(Movimientos!H2:H594,Movimientos!B2:B594,Vehículos!A9,Movimientos!E2:E594,"Gasto administrativo"),0) | H13: =E13+F13+G13 | I13: =IFERROR(H13/E13,"-") | J13: =COUNTIF(Movimientos!B2:B594,Vehículos!A9) | K13: =IF(COUNTIF(Movimientos!B2:B594,Vehículos!A9)=0,"—",IF(H13>0,"🟢 Rentable",IF(H13>-500000,"🟡 Atención","🔴 Pérdida alta")))
B14: =Vehículos!A10 | C14: =IFERROR(VLOOKUP(Vehículos!A10,Vehículos!A:E,5,FALSE()),"") | D14: =IFERROR(VLOOKUP(Vehículos!A10,Vehículos!A:I,9,FALSE()),"") | E14: =IFERROR(SUMIFS(Movimientos!H2:H594,Movimientos!B2:B594,Vehículos!A10,Movimientos!D2:D594,"Ingreso"),0) | F14: =IFERROR(SUMIFS(Movimientos!H2:H594,Movimientos!B2:B594,Vehículos!A10,Movimientos!E2:E594,"Gasto administrativo"),0) | G14: =IFERROR(SUMIFS(Movimientos!H2:H594,Movimientos!B2:B594,Vehículos!A10,Movimientos!D2:D594,"Gasto")-SUMIFS(Movimientos!H2:H594,Movimientos!B2:B594,Vehículos!A10,Movimientos!E2:E594,"Gasto administrativo"),0) | H14: =E14+F14+G14 | I14: =IFERROR(H14/E14,"-") | J14: =COUNTIF(Movimientos!B2:B594,Vehículos!A10) | K14: =IF(COUNTIF(Movimientos!B2:B594,Vehículos!A10)=0,"—",IF(H14>0,"🟢 Rentable",IF(H14>-500000,"🟡 Atención","🔴 Pérdida alta")))
B15: =Vehículos!A11 | C15: =IFERROR(VLOOKUP(Vehículos!A11,Vehículos!A:E,5,FALSE()),"") | D15: =IFERROR(VLOOKUP(Vehículos!A11,Vehículos!A:I,9,FALSE()),"") | E15: =IFERROR(SUMIFS(Movimientos!H2:H594,Movimientos!B2:B594,Vehículos!A11,Movimientos!D2:D594,"Ingreso"),0) | F15: =IFERROR(SUMIFS(Movimientos!H2:H594,Movimientos!B2:B594,Vehículos!A11,Movimientos!E2:E594,"Gasto administrativo"),0) | G15: =IFERROR(SUMIFS(Movimientos!H2:H594,Movimientos!B2:B594,Vehículos!A11,Movimientos!D2:D594,"Gasto")-SUMIFS(Movimientos!H2:H594,Movimientos!B2:B594,Vehículos!A11,Movimientos!E2:E594,"Gasto administrativo"),0) | H15: =E15+F15+G15 | I15: =IFERROR(H15/E15,"-") | J15: =COUNTIF(Movimientos!B2:B594,Vehículos!A11) | K15: =IF(COUNTIF(Movimientos!B2:B594,Vehículos!A11)=0,"—",IF(H15>0,"🟢 Rentable",IF(H15>-500000,"🟡 Atención","🔴 Pérdida alta")))
B16: =Vehículos!A12 | C16: =IFERROR(VLOOKUP(Vehículos!A12,Vehículos!A:E,5,FALSE()),"") | D16: =IFERROR(VLOOKUP(Vehículos!A12,Vehículos!A:I,9,FALSE()),"") | E16: =IFERROR(SUMIFS(Movimientos!H2:H594,Movimientos!B2:B594,Vehículos!A12,Movimientos!D2:D594,"Ingreso"),0) | F16: =IFERROR(SUMIFS(Movimientos!H2:H594,Movimientos!B2:B594,Vehículos!A12,Movimientos!E2:E594,"Gasto administrativo"),0) | G16: =IFERROR(SUMIFS(Movimientos!H2:H594,Movimientos!B2:B594,Vehículos!A12,Movimientos!D2:D594,"Gasto")-SUMIFS(Movimientos!H2:H594,Movimientos!B2:B594,Vehículos!A12,Movimientos!E2:E594,"Gasto administrativo"),0) | H16: =E16+F16+G16 | I16: =IFERROR(H16/E16,"-") | J16: =COUNTIF(Movimientos!B2:B594,Vehículos!A12) | K16: =IF(COUNTIF(Movimientos!B2:B594,Vehículos!A12)=0,"—",IF(H16>0,"🟢 Rentable",IF(H16>-500000,"🟡 Atención","🔴 Pérdida alta")))
B17: =Vehículos!A13 | C17: =IFERROR(VLOOKUP(Vehículos!A13,Vehículos!A:E,5,FALSE()),"") | D17: =IFERROR(VLOOKUP(Vehículos!A13,Vehículos!A:I,9,FALSE()),"") | E17: =IFERROR(SUMIFS(Movimientos!H2:H594,Movimientos!B2:B594,Vehículos!A13,Movimientos!D2:D594,"Ingreso"),0) | F17: =IFERROR(SUMIFS(Movimientos!H2:H594,Movimientos!B2:B594,Vehículos!A13,Movimientos!E2:E594,"Gasto administrativo"),0) | G17: =IFERROR(SUMIFS(Movimientos!H2:H594,Movimientos!B2:B594,Vehículos!A13,Movimientos!D2:D594,"Gasto")-SUMIFS(Movimientos!H2:H594,Movimientos!B2:B594,Vehículos!A13,Movimientos!E2:E594,"Gasto administrativo"),0) | H17: =E17+F17+G17 | I17: =IFERROR(H17/E17,"-") | J17: =COUNTIF(Movimientos!B2:B594,Vehículos!A13) | K17: =IF(COUNTIF(Movimientos!B2:B594,Vehículos!A13)=0,"—",IF(H17>0,"🟢 Rentable",IF(H17>-500000,"🟡 Atención","🔴 Pérdida alta")))
B18: =Vehículos!A14 | C18: =IFERROR(VLOOKUP(Vehículos!A14,Vehículos!A:E,5,FALSE()),"") | D18: =IFERROR(VLOOKUP(Vehículos!A14,Vehículos!A:I,9,FALSE()),"") | E18: =IFERROR(SUMIFS(Movimientos!H2:H594,Movimientos!B2:B594,Vehículos!A14,Movimientos!D2:D594,"Ingreso"),0) | F18: =IFERROR(SUMIFS(Movimientos!H2:H594,Movimientos!B2:B594,Vehículos!A14,Movimientos!E2:E594,"Gasto administrativo"),0) | G18: =IFERROR(SUMIFS(Movimientos!H2:H594,Movimientos!B2:B594,Vehículos!A14,Movimientos!D2:D594,"Gasto")-SUMIFS(Movimientos!H2:H594,Movimientos!B2:B594,Vehículos!A14,Movimientos!E2:E594,"Gasto administrativo"),0) | H18: =E18+F18+G18 | I18: =IFERROR(H18/E18,"-") | J18: =COUNTIF(Movimientos!B2:B594,Vehículos!A14) | K18: =IF(COUNTIF(Movimientos!B2:B594,Vehículos!A14)=0,"—",IF(H18>0,"🟢 Rentable",IF(H18>-500000,"🟡 Atención","🔴 Pérdida alta")))
B19: =Vehículos!A15 | C19: =IFERROR(VLOOKUP(Vehículos!A15,Vehículos!A:E,5,FALSE()),"") | D19: =IFERROR(VLOOKUP(Vehículos!A15,Vehículos!A:I,9,FALSE()),"") | E19: =IFERROR(SUMIFS(Movimientos!H2:H594,Movimientos!B2:B594,Vehículos!A15,Movimientos!D2:D594,"Ingreso"),0) | F19: =IFERROR(SUMIFS(Movimientos!H2:H594,Movimientos!B2:B594,Vehículos!A15,Movimientos!E2:E594,"Gasto administrativo"),0) | G19: =IFERROR(SUMIFS(Movimientos!H2:H594,Movimientos!B2:B594,Vehículos!A15,Movimientos!D2:D594,"Gasto")-SUMIFS(Movimientos!H2:H594,Movimientos!B2:B594,Vehículos!A15,Movimientos!E2:E594,"Gasto administrativo"),0) | H19: =E19+F19+G19 | I19: =IFERROR(H19/E19,"-") | J19: =COUNTIF(Movimientos!B2:B594,Vehículos!A15) | K19: =IF(COUNTIF(Movimientos!B2:B594,Vehículos!A15)=0,"—",IF(H19>0,"🟢 Rentable",IF(H19>-500000,"🟡 Atención","🔴 Pérdida alta")))
B20: =Vehículos!A16 | C20: =IFERROR(VLOOKUP(Vehículos!A16,Vehículos!A:E,5,FALSE()),"") | D20: =IFERROR(VLOOKUP(Vehículos!A16,Vehículos!A:I,9,FALSE()),"") | E20: =IFERROR(SUMIFS(Movimientos!H2:H594,Movimientos!B2:B594,Vehículos!A16,Movimientos!D2:D594,"Ingreso"),0) | F20: =IFERROR(SUMIFS(Movimientos!H2:H594,Movimientos!B2:B594,Vehículos!A16,Movimientos!E2:E594,"Gasto administrativo"),0) | G20: =IFERROR(SUMIFS(Movimientos!H2:H594,Movimientos!B2:B594,Vehículos!A16,Movimientos!D2:D594,"Gasto")-SUMIFS(Movimientos!H2:H594,Movimientos!B2:B594,Vehículos!A16,Movimientos!E2:E594,"Gasto administrativo"),0) | H20: =E20+F20+G20 | I20: =IFERROR(H20/E20,"-") | J20: =COUNTIF(Movimientos!B2:B594,Vehículos!A16) | K20: =IF(COUNTIF(Movimientos!B2:B594,Vehículos!A16)=0,"—",IF(H20>0,"🟢 Rentable",IF(H20>-500000,"🟡 Atención","🔴 Pérdida alta")))
B21: =Vehículos!A17 | C21: =IFERROR(VLOOKUP(Vehículos!A17,Vehículos!A:E,5,FALSE()),"") | D21: =IFERROR(VLOOKUP(Vehículos!A17,Vehículos!A:I,9,FALSE()),"") | E21: =IFERROR(SUMIFS(Movimientos!H2:H594,Movimientos!B2:B594,Vehículos!A17,Movimientos!D2:D594,"Ingreso"),0) | F21: =IFERROR(SUMIFS(Movimientos!H2:H594,Movimientos!B2:B594,Vehículos!A17,Movimientos!E2:E594,"Gasto administrativo"),0) | G21: =IFERROR(SUMIFS(Movimientos!H2:H594,Movimientos!B2:B594,Vehículos!A17,Movimientos!D2:D594,"Gasto")-SUMIFS(Movimientos!H2:H594,Movimientos!B2:B594,Vehículos!A17,Movimientos!E2:E594,"Gasto administrativo"),0) | H21: =E21+F21+G21 | I21: =IFERROR(H21/E21,"-") | J21: =COUNTIF(Movimientos!B2:B594,Vehículos!A17) | K21: =IF(COUNTIF(Movimientos!B2:B594,Vehículos!A17)=0,"—",IF(H21>0,"🟢 Rentable",IF(H21>-500000,"🟡 Atención","🔴 Pérdida alta")))
B22: =Vehículos!A18 | C22: =IFERROR(VLOOKUP(Vehículos!A18,Vehículos!A:E,5,FALSE()),"") | D22: =IFERROR(VLOOKUP(Vehículos!A18,Vehículos!A:I,9,FALSE()),"") | E22: =IFERROR(SUMIFS(Movimientos!H2:H594,Movimientos!B2:B594,Vehículos!A18,Movimientos!D2:D594,"Ingreso"),0) | F22: =IFERROR(SUMIFS(Movimientos!H2:H594,Movimientos!B2:B594,Vehículos!A18,Movimientos!E2:E594,"Gasto administrativo"),0) | G22: =IFERROR(SUMIFS(Movimientos!H2:H594,Movimientos!B2:B594,Vehículos!A18,Movimientos!D2:D594,"Gasto")-SUMIFS(Movimientos!H2:H594,Movimientos!B2:B594,Vehículos!A18,Movimientos!E2:E594,"Gasto administrativo"),0) | H22: =E22+F22+G22 | I22: =IFERROR(H22/E22,"-") | J22: =COUNTIF(Movimientos!B2:B594,Vehículos!A18) | K22: =IF(COUNTIF(Movimientos!B2:B594,Vehículos!A18)=0,"—",IF(H22>0,"🟢 Rentable",IF(H22>-500000,"🟡 Atención","🔴 Pérdida alta")))
B23: =Vehículos!A19 | C23: =IFERROR(VLOOKUP(Vehículos!A19,Vehículos!A:E,5,FALSE()),"") | D23: =IFERROR(VLOOKUP(Vehículos!A19,Vehículos!A:I,9,FALSE()),"") | E23: =IFERROR(SUMIFS(Movimientos!H2:H594,Movimientos!B2:B594,Vehículos!A19,Movimientos!D2:D594,"Ingreso"),0) | F23: =IFERROR(SUMIFS(Movimientos!H2:H594,Movimientos!B2:B594,Vehículos!A19,Movimientos!E2:E594,"Gasto administrativo"),0) | G23: =IFERROR(SUMIFS(Movimientos!H2:H594,Movimientos!B2:B594,Vehículos!A19,Movimientos!D2:D594,"Gasto")-SUMIFS(Movimientos!H2:H594,Movimientos!B2:B594,Vehículos!A19,Movimientos!E2:E594,"Gasto administrativo"),0) | H23: =E23+F23+G23 | I23: =IFERROR(H23/E23,"-") | J23: =COUNTIF(Movimientos!B2:B594,Vehículos!A19) | K23: =IF(COUNTIF(Movimientos!B2:B594,Vehículos!A19)=0,"—",IF(H23>0,"🟢 Rentable",IF(H23>-500000,"🟡 Atención","🔴 Pérdida alta")))
B24: =Vehículos!A20 | C24: =IFERROR(VLOOKUP(Vehículos!A20,Vehículos!A:E,5,FALSE()),"") | D24: =IFERROR(VLOOKUP(Vehículos!A20,Vehículos!A:I,9,FALSE()),"") | E24: =IFERROR(SUMIFS(Movimientos!H2:H594,Movimientos!B2:B594,Vehículos!A20,Movimientos!D2:D594,"Ingreso"),0) | F24: =IFERROR(SUMIFS(Movimientos!H2:H594,Movimientos!B2:B594,Vehículos!A20,Movimientos!E2:E594,"Gasto administrativo"),0) | G24: =IFERROR(SUMIFS(Movimientos!H2:H594,Movimientos!B2:B594,Vehículos!A20,Movimientos!D2:D594,"Gasto")-SUMIFS(Movimientos!H2:H594,Movimientos!B2:B594,Vehículos!A20,Movimientos!E2:E594,"Gasto administrativo"),0) | H24: =E24+F24+G24 | I24: =IFERROR(H24/E24,"-") | J24: =COUNTIF(Movimientos!B2:B594,Vehículos!A20) | K24: =IF(COUNTIF(Movimientos!B2:B594,Vehículos!A20)=0,"—",IF(H24>0,"🟢 Rentable",IF(H24>-500000,"🟡 Atención","🔴 Pérdida alta")))
B25: =Vehículos!A21 | C25: =IFERROR(VLOOKUP(Vehículos!A21,Vehículos!A:E,5,FALSE()),"") | D25: =IFERROR(VLOOKUP(Vehículos!A21,Vehículos!A:I,9,FALSE()),"") | E25: =IFERROR(SUMIFS(Movimientos!H2:H594,Movimientos!B2:B594,Vehículos!A21,Movimientos!D2:D594,"Ingreso"),0) | F25: =IFERROR(SUMIFS(Movimientos!H2:H594,Movimientos!B2:B594,Vehículos!A21,Movimientos!E2:E594,"Gasto administrativo"),0) | G25: =IFERROR(SUMIFS(Movimientos!H2:H594,Movimientos!B2:B594,Vehículos!A21,Movimientos!D2:D594,"Gasto")-SUMIFS(Movimientos!H2:H594,Movimientos!B2:B594,Vehículos!A21,Movimientos!E2:E594,"Gasto administrativo"),0) | H25: =E25+F25+G25 | I25: =IFERROR(H25/E25,"-") | J25: =COUNTIF(Movimientos!B2:B594,Vehículos!A21) | K25: =IF(COUNTIF(Movimientos!B2:B594,Vehículos!A21)=0,"—",IF(H25>0,"🟢 Rentable",IF(H25>-500000,"🟡 Atención","🔴 Pérdida alta")))
B26: TOTAL FLOTA | E26: =SUM(E6:E25) | F26: =SUM(F6:F25) | G26: =SUM(G6:G25) | H26: =SUM(H6:H25) | I26: =IFERROR(H26/E26,"-") | J26: =SUM(J6:J25)
